2020-08-02 11:48:18,839 ERROR: Exception on /login [GET] [in C:\Users\aless\Anaconda3\envs\flask_env\lib\site-packages\flask\app.py:1891]
Traceback (most recent call last):
  File "C:\Users\aless\Anaconda3\envs\flask_env\lib\site-packages\flask\app.py", line 2447, in wsgi_app
    response = self.full_dispatch_request()
  File "C:\Users\aless\Anaconda3\envs\flask_env\lib\site-packages\flask\app.py", line 1952, in full_dispatch_request
    rv = self.handle_user_exception(e)
  File "C:\Users\aless\Anaconda3\envs\flask_env\lib\site-packages\flask\app.py", line 1821, in handle_user_exception
    reraise(exc_type, exc_value, tb)
  File "C:\Users\aless\Anaconda3\envs\flask_env\lib\site-packages\flask\_compat.py", line 39, in reraise
    raise value
  File "C:\Users\aless\Anaconda3\envs\flask_env\lib\site-packages\flask\app.py", line 1950, in full_dispatch_request
    rv = self.dispatch_request()
  File "C:\Users\aless\Anaconda3\envs\flask_env\lib\site-packages\flask\app.py", line 1936, in dispatch_request
    return self.view_functions[rule.endpoint](**req.view_args)
  File "C:\Users\aless\Desktop\AI\CORSI\web_flask\microblog\app\routes.py", line 67, in login
    return render_template('login.html', title='Sign In', form=form)
  File "C:\Users\aless\Anaconda3\envs\flask_env\lib\site-packages\flask\templating.py", line 138, in render_template
    ctx.app.jinja_env.get_or_select_template(template_name_or_list),
  File "C:\Users\aless\Anaconda3\envs\flask_env\lib\site-packages\jinja2\environment.py", line 930, in get_or_select_template
    return self.get_template(template_name_or_list, parent, globals)
  File "C:\Users\aless\Anaconda3\envs\flask_env\lib\site-packages\jinja2\environment.py", line 883, in get_template
    return self._load_template(name, self.make_globals(globals))
  File "C:\Users\aless\Anaconda3\envs\flask_env\lib\site-packages\jinja2\environment.py", line 857, in _load_template
    template = self.loader.load(self, name, globals)
  File "C:\Users\aless\Anaconda3\envs\flask_env\lib\site-packages\jinja2\loaders.py", line 127, in load
    code = environment.compile(source, name, filename)
  File "C:\Users\aless\Anaconda3\envs\flask_env\lib\site-packages\jinja2\environment.py", line 638, in compile
    self.handle_exception(source=source_hint)
  File "C:\Users\aless\Anaconda3\envs\flask_env\lib\site-packages\jinja2\environment.py", line 832, in handle_exception
    reraise(*rewrite_traceback_stack(source=source))
  File "C:\Users\aless\Anaconda3\envs\flask_env\lib\site-packages\jinja2\_compat.py", line 28, in reraise
    raise value.with_traceback(tb)
  File "C:\Users\aless\Desktop\AI\CORSI\web_flask\microblog\app\templates\login.html", line 15, in template
    <a href="{{ url_for('auth.reset_password_request') }}">{{ _(Clilck to Reset it) }}</a>
jinja2.exceptions.TemplateSyntaxError: expected token ',', got 'to'
2020-08-02 11:50:56,145 INFO: Microblog startup [in C:\Users\aless\Desktop\AI\CORSI\web_flask\microblog\app\__init__.py:49]
2020-08-02 11:51:01,945 ERROR: Exception on /login [GET] [in C:\Users\aless\Anaconda3\envs\flask_env\lib\site-packages\flask\app.py:1891]
Traceback (most recent call last):
  File "C:\Users\aless\Anaconda3\envs\flask_env\lib\site-packages\flask\app.py", line 2447, in wsgi_app
    response = self.full_dispatch_request()
  File "C:\Users\aless\Anaconda3\envs\flask_env\lib\site-packages\flask\app.py", line 1952, in full_dispatch_request
    rv = self.handle_user_exception(e)
  File "C:\Users\aless\Anaconda3\envs\flask_env\lib\site-packages\flask\app.py", line 1821, in handle_user_exception
    reraise(exc_type, exc_value, tb)
  File "C:\Users\aless\Anaconda3\envs\flask_env\lib\site-packages\flask\_compat.py", line 39, in reraise
    raise value
  File "C:\Users\aless\Anaconda3\envs\flask_env\lib\site-packages\flask\app.py", line 1950, in full_dispatch_request
    rv = self.dispatch_request()
  File "C:\Users\aless\Anaconda3\envs\flask_env\lib\site-packages\flask\app.py", line 1936, in dispatch_request
    return self.view_functions[rule.endpoint](**req.view_args)
  File "C:\Users\aless\Desktop\AI\CORSI\web_flask\microblog\app\routes.py", line 67, in login
    return render_template('login.html', title='Sign In', form=form)
  File "C:\Users\aless\Anaconda3\envs\flask_env\lib\site-packages\flask\templating.py", line 138, in render_template
    ctx.app.jinja_env.get_or_select_template(template_name_or_list),
  File "C:\Users\aless\Anaconda3\envs\flask_env\lib\site-packages\jinja2\environment.py", line 930, in get_or_select_template
    return self.get_template(template_name_or_list, parent, globals)
  File "C:\Users\aless\Anaconda3\envs\flask_env\lib\site-packages\jinja2\environment.py", line 883, in get_template
    return self._load_template(name, self.make_globals(globals))
  File "C:\Users\aless\Anaconda3\envs\flask_env\lib\site-packages\jinja2\environment.py", line 857, in _load_template
    template = self.loader.load(self, name, globals)
  File "C:\Users\aless\Anaconda3\envs\flask_env\lib\site-packages\jinja2\loaders.py", line 127, in load
    code = environment.compile(source, name, filename)
  File "C:\Users\aless\Anaconda3\envs\flask_env\lib\site-packages\jinja2\environment.py", line 638, in compile
    self.handle_exception(source=source_hint)
  File "C:\Users\aless\Anaconda3\envs\flask_env\lib\site-packages\jinja2\environment.py", line 832, in handle_exception
    reraise(*rewrite_traceback_stack(source=source))
  File "C:\Users\aless\Anaconda3\envs\flask_env\lib\site-packages\jinja2\_compat.py", line 28, in reraise
    raise value.with_traceback(tb)
  File "C:\Users\aless\Desktop\AI\CORSI\web_flask\microblog\app\templates\login.html", line 21, in template
    <!-- {% block app_content %}
jinja2.exceptions.TemplateAssertionError: block 'app_content' defined twice
2020-08-02 11:59:43,920 INFO: Microblog startup [in C:\Users\aless\Desktop\AI\CORSI\web_flask\microblog\app\__init__.py:49]
2020-08-02 11:59:47,949 ERROR: Exception on /login [GET] [in C:\Users\aless\Anaconda3\envs\flask_env\lib\site-packages\flask\app.py:1891]
Traceback (most recent call last):
  File "C:\Users\aless\Anaconda3\envs\flask_env\lib\site-packages\flask\app.py", line 2447, in wsgi_app
    response = self.full_dispatch_request()
  File "C:\Users\aless\Anaconda3\envs\flask_env\lib\site-packages\flask\app.py", line 1952, in full_dispatch_request
    rv = self.handle_user_exception(e)
  File "C:\Users\aless\Anaconda3\envs\flask_env\lib\site-packages\flask\app.py", line 1821, in handle_user_exception
    reraise(exc_type, exc_value, tb)
  File "C:\Users\aless\Anaconda3\envs\flask_env\lib\site-packages\flask\_compat.py", line 39, in reraise
    raise value
  File "C:\Users\aless\Anaconda3\envs\flask_env\lib\site-packages\flask\app.py", line 1950, in full_dispatch_request
    rv = self.dispatch_request()
  File "C:\Users\aless\Anaconda3\envs\flask_env\lib\site-packages\flask\app.py", line 1936, in dispatch_request
    return self.view_functions[rule.endpoint](**req.view_args)
  File "C:\Users\aless\Desktop\AI\CORSI\web_flask\microblog\app\routes.py", line 67, in login
    return render_template('login.html', title='Sign In', form=form)
  File "C:\Users\aless\Anaconda3\envs\flask_env\lib\site-packages\flask\templating.py", line 138, in render_template
    ctx.app.jinja_env.get_or_select_template(template_name_or_list),
  File "C:\Users\aless\Anaconda3\envs\flask_env\lib\site-packages\jinja2\environment.py", line 930, in get_or_select_template
    return self.get_template(template_name_or_list, parent, globals)
  File "C:\Users\aless\Anaconda3\envs\flask_env\lib\site-packages\jinja2\environment.py", line 883, in get_template
    return self._load_template(name, self.make_globals(globals))
  File "C:\Users\aless\Anaconda3\envs\flask_env\lib\site-packages\jinja2\environment.py", line 857, in _load_template
    template = self.loader.load(self, name, globals)
  File "C:\Users\aless\Anaconda3\envs\flask_env\lib\site-packages\jinja2\loaders.py", line 127, in load
    code = environment.compile(source, name, filename)
  File "C:\Users\aless\Anaconda3\envs\flask_env\lib\site-packages\jinja2\environment.py", line 638, in compile
    self.handle_exception(source=source_hint)
  File "C:\Users\aless\Anaconda3\envs\flask_env\lib\site-packages\jinja2\environment.py", line 832, in handle_exception
    reraise(*rewrite_traceback_stack(source=source))
  File "C:\Users\aless\Anaconda3\envs\flask_env\lib\site-packages\jinja2\_compat.py", line 28, in reraise
    raise value.with_traceback(tb)
  File "C:\Users\aless\Desktop\AI\CORSI\web_flask\microblog\app\templates\login.html", line 21, in template
    <!-- {% block app_content %}
jinja2.exceptions.TemplateAssertionError: block 'app_content' defined twice
2020-08-02 12:32:32,106 INFO: Microblog startup [in C:\Users\aless\Desktop\AI\CORSI\web_flask\microblog\app\__init__.py:49]
2020-08-02 12:37:46,953 INFO: Microblog startup [in C:\Users\aless\Desktop\AI\CORSI\web_flask\microblog\app\__init__.py:49]
