2020-07-25 17:39:03,874 ERROR: Exception on /index [POST] [in C:\Users\aless\Anaconda3\envs\flask_env\lib\site-packages\flask\app.py:1891]
Traceback (most recent call last):
  File "C:\Users\aless\Anaconda3\envs\flask_env\lib\site-packages\flask\app.py", line 2447, in wsgi_app
    response = self.full_dispatch_request()
  File "C:\Users\aless\Anaconda3\envs\flask_env\lib\site-packages\flask\app.py", line 1952, in full_dispatch_request
    rv = self.handle_user_exception(e)
  File "C:\Users\aless\Anaconda3\envs\flask_env\lib\site-packages\flask\app.py", line 1821, in handle_user_exception
    reraise(exc_type, exc_value, tb)
  File "C:\Users\aless\Anaconda3\envs\flask_env\lib\site-packages\flask\_compat.py", line 39, in reraise
    raise value
  File "C:\Users\aless\Anaconda3\envs\flask_env\lib\site-packages\flask\app.py", line 1950, in full_dispatch_request
    rv = self.dispatch_request()
  File "C:\Users\aless\Anaconda3\envs\flask_env\lib\site-packages\flask\app.py", line 1936, in dispatch_request
    return self.view_functions[rule.endpoint](**req.view_args)
  File "C:\Users\aless\Anaconda3\envs\flask_env\lib\site-packages\flask_login\utils.py", line 272, in decorated_view
    return func(*args, **kwargs)
  File "C:\Users\aless\Desktop\AI\CORSI\web_flask\microblog\app\routes.py", line 23, in index
    db.session.add()
  File "C:\Users\aless\Anaconda3\envs\flask_env\lib\site-packages\sqlalchemy\orm\scoping.py", line 163, in do
    return getattr(self.registry(), name)(*args, **kwargs)
TypeError: add() missing 1 required positional argument: 'instance'
2020-07-25 17:39:15,735 ERROR: Exception on /index [POST] [in C:\Users\aless\Anaconda3\envs\flask_env\lib\site-packages\flask\app.py:1891]
Traceback (most recent call last):
  File "C:\Users\aless\Anaconda3\envs\flask_env\lib\site-packages\flask\app.py", line 2447, in wsgi_app
    response = self.full_dispatch_request()
  File "C:\Users\aless\Anaconda3\envs\flask_env\lib\site-packages\flask\app.py", line 1952, in full_dispatch_request
    rv = self.handle_user_exception(e)
  File "C:\Users\aless\Anaconda3\envs\flask_env\lib\site-packages\flask\app.py", line 1821, in handle_user_exception
    reraise(exc_type, exc_value, tb)
  File "C:\Users\aless\Anaconda3\envs\flask_env\lib\site-packages\flask\_compat.py", line 39, in reraise
    raise value
  File "C:\Users\aless\Anaconda3\envs\flask_env\lib\site-packages\flask\app.py", line 1950, in full_dispatch_request
    rv = self.dispatch_request()
  File "C:\Users\aless\Anaconda3\envs\flask_env\lib\site-packages\flask\app.py", line 1936, in dispatch_request
    return self.view_functions[rule.endpoint](**req.view_args)
  File "C:\Users\aless\Anaconda3\envs\flask_env\lib\site-packages\flask_login\utils.py", line 272, in decorated_view
    return func(*args, **kwargs)
  File "C:\Users\aless\Desktop\AI\CORSI\web_flask\microblog\app\routes.py", line 23, in index
    db.session.add()
  File "C:\Users\aless\Anaconda3\envs\flask_env\lib\site-packages\sqlalchemy\orm\scoping.py", line 163, in do
    return getattr(self.registry(), name)(*args, **kwargs)
TypeError: add() missing 1 required positional argument: 'instance'
2020-07-26 11:24:44,671 INFO: Microblog startup [in C:\Users\aless\Desktop\AI\CORSI\web_flask\microblog\app\__init__.py:45]
2020-07-26 11:30:09,646 INFO: Microblog startup [in C:\Users\aless\Desktop\AI\CORSI\web_flask\microblog\app\__init__.py:45]
2020-07-26 11:49:34,174 INFO: Microblog startup [in C:\Users\aless\Desktop\AI\CORSI\web_flask\microblog\app\__init__.py:45]
2020-07-26 12:51:29,057 INFO: Microblog startup [in C:\Users\aless\Desktop\AI\CORSI\web_flask\microblog\app\__init__.py:45]
2020-07-26 12:51:52,291 ERROR: Exception on /explore [GET] [in C:\Users\aless\Anaconda3\envs\flask_env\lib\site-packages\flask\app.py:1891]
Traceback (most recent call last):
  File "C:\Users\aless\Anaconda3\envs\flask_env\lib\site-packages\flask\app.py", line 2447, in wsgi_app
    response = self.full_dispatch_request()
  File "C:\Users\aless\Anaconda3\envs\flask_env\lib\site-packages\flask\app.py", line 1952, in full_dispatch_request
    rv = self.handle_user_exception(e)
  File "C:\Users\aless\Anaconda3\envs\flask_env\lib\site-packages\flask\app.py", line 1821, in handle_user_exception
    reraise(exc_type, exc_value, tb)
  File "C:\Users\aless\Anaconda3\envs\flask_env\lib\site-packages\flask\_compat.py", line 39, in reraise
    raise value
  File "C:\Users\aless\Anaconda3\envs\flask_env\lib\site-packages\flask\app.py", line 1950, in full_dispatch_request
    rv = self.dispatch_request()
  File "C:\Users\aless\Anaconda3\envs\flask_env\lib\site-packages\flask\app.py", line 1936, in dispatch_request
    return self.view_functions[rule.endpoint](**req.view_args)
  File "C:\Users\aless\Anaconda3\envs\flask_env\lib\site-packages\flask_login\utils.py", line 272, in decorated_view
    return func(*args, **kwargs)
  File "C:\Users\aless\Desktop\AI\CORSI\web_flask\microblog\app\routes.py", line 171, in explore
    page = requests.args.get('page', 1, type=int)
NameError: name 'requests' is not defined
2020-07-26 12:51:56,797 ERROR: Exception on /explore [GET] [in C:\Users\aless\Anaconda3\envs\flask_env\lib\site-packages\flask\app.py:1891]
Traceback (most recent call last):
  File "C:\Users\aless\Anaconda3\envs\flask_env\lib\site-packages\flask\app.py", line 2447, in wsgi_app
    response = self.full_dispatch_request()
  File "C:\Users\aless\Anaconda3\envs\flask_env\lib\site-packages\flask\app.py", line 1952, in full_dispatch_request
    rv = self.handle_user_exception(e)
  File "C:\Users\aless\Anaconda3\envs\flask_env\lib\site-packages\flask\app.py", line 1821, in handle_user_exception
    reraise(exc_type, exc_value, tb)
  File "C:\Users\aless\Anaconda3\envs\flask_env\lib\site-packages\flask\_compat.py", line 39, in reraise
    raise value
  File "C:\Users\aless\Anaconda3\envs\flask_env\lib\site-packages\flask\app.py", line 1950, in full_dispatch_request
    rv = self.dispatch_request()
  File "C:\Users\aless\Anaconda3\envs\flask_env\lib\site-packages\flask\app.py", line 1936, in dispatch_request
    return self.view_functions[rule.endpoint](**req.view_args)
  File "C:\Users\aless\Anaconda3\envs\flask_env\lib\site-packages\flask_login\utils.py", line 272, in decorated_view
    return func(*args, **kwargs)
  File "C:\Users\aless\Desktop\AI\CORSI\web_flask\microblog\app\routes.py", line 171, in explore
    page = requests.args.get('page', 1, type=int)
NameError: name 'requests' is not defined
2020-07-26 12:52:01,223 ERROR: Exception on /explore [GET] [in C:\Users\aless\Anaconda3\envs\flask_env\lib\site-packages\flask\app.py:1891]
Traceback (most recent call last):
  File "C:\Users\aless\Anaconda3\envs\flask_env\lib\site-packages\flask\app.py", line 2447, in wsgi_app
    response = self.full_dispatch_request()
  File "C:\Users\aless\Anaconda3\envs\flask_env\lib\site-packages\flask\app.py", line 1952, in full_dispatch_request
    rv = self.handle_user_exception(e)
  File "C:\Users\aless\Anaconda3\envs\flask_env\lib\site-packages\flask\app.py", line 1821, in handle_user_exception
    reraise(exc_type, exc_value, tb)
  File "C:\Users\aless\Anaconda3\envs\flask_env\lib\site-packages\flask\_compat.py", line 39, in reraise
    raise value
  File "C:\Users\aless\Anaconda3\envs\flask_env\lib\site-packages\flask\app.py", line 1950, in full_dispatch_request
    rv = self.dispatch_request()
  File "C:\Users\aless\Anaconda3\envs\flask_env\lib\site-packages\flask\app.py", line 1936, in dispatch_request
    return self.view_functions[rule.endpoint](**req.view_args)
  File "C:\Users\aless\Anaconda3\envs\flask_env\lib\site-packages\flask_login\utils.py", line 272, in decorated_view
    return func(*args, **kwargs)
  File "C:\Users\aless\Desktop\AI\CORSI\web_flask\microblog\app\routes.py", line 171, in explore
    page = requests.args.get('page', 1, type=int)
NameError: name 'requests' is not defined
2020-07-26 12:52:13,430 ERROR: Exception on /explore [GET] [in C:\Users\aless\Anaconda3\envs\flask_env\lib\site-packages\flask\app.py:1891]
Traceback (most recent call last):
  File "C:\Users\aless\Anaconda3\envs\flask_env\lib\site-packages\flask\app.py", line 2447, in wsgi_app
    response = self.full_dispatch_request()
  File "C:\Users\aless\Anaconda3\envs\flask_env\lib\site-packages\flask\app.py", line 1952, in full_dispatch_request
    rv = self.handle_user_exception(e)
  File "C:\Users\aless\Anaconda3\envs\flask_env\lib\site-packages\flask\app.py", line 1821, in handle_user_exception
    reraise(exc_type, exc_value, tb)
  File "C:\Users\aless\Anaconda3\envs\flask_env\lib\site-packages\flask\_compat.py", line 39, in reraise
    raise value
  File "C:\Users\aless\Anaconda3\envs\flask_env\lib\site-packages\flask\app.py", line 1950, in full_dispatch_request
    rv = self.dispatch_request()
  File "C:\Users\aless\Anaconda3\envs\flask_env\lib\site-packages\flask\app.py", line 1936, in dispatch_request
    return self.view_functions[rule.endpoint](**req.view_args)
  File "C:\Users\aless\Anaconda3\envs\flask_env\lib\site-packages\flask_login\utils.py", line 272, in decorated_view
    return func(*args, **kwargs)
  File "C:\Users\aless\Desktop\AI\CORSI\web_flask\microblog\app\routes.py", line 171, in explore
    page = requests.args.get('page', 1, type=int)
NameError: name 'requests' is not defined
2020-07-26 12:53:38,824 INFO: Microblog startup [in C:\Users\aless\Desktop\AI\CORSI\web_flask\microblog\app\__init__.py:45]
2020-07-26 21:26:29,154 INFO: Microblog startup [in C:\Users\aless\Desktop\AI\CORSI\web_flask\microblog\app\__init__.py:45]
2020-07-26 21:43:49,728 INFO: Microblog startup [in C:\Users\aless\Desktop\AI\CORSI\web_flask\microblog\app\__init__.py:45]
2020-07-27 10:30:08,438 INFO: Microblog startup [in C:\Users\aless\Desktop\AI\CORSI\web_flask\microblog\app\__init__.py:47]
2020-07-27 15:37:13,764 INFO: Microblog startup [in C:\Users\aless\Desktop\AI\CORSI\web_flask\microblog\app\__init__.py:47]
2020-07-27 15:39:48,562 INFO: Microblog startup [in C:\Users\aless\Desktop\AI\CORSI\web_flask\microblog\app\__init__.py:47]
