2020-07-27 15:40:32,510 ERROR: Exception on /reset_password_request [POST] [in C:\Users\aless\Anaconda3\envs\flask_env\lib\site-packages\flask\app.py:1891]
Traceback (most recent call last):
  File "C:\Users\aless\Anaconda3\envs\flask_env\lib\site-packages\flask\app.py", line 2447, in wsgi_app
    response = self.full_dispatch_request()
  File "C:\Users\aless\Anaconda3\envs\flask_env\lib\site-packages\flask\app.py", line 1952, in full_dispatch_request
    rv = self.handle_user_exception(e)
  File "C:\Users\aless\Anaconda3\envs\flask_env\lib\site-packages\flask\app.py", line 1821, in handle_user_exception
    reraise(exc_type, exc_value, tb)
  File "C:\Users\aless\Anaconda3\envs\flask_env\lib\site-packages\flask\_compat.py", line 39, in reraise
    raise value
  File "C:\Users\aless\Anaconda3\envs\flask_env\lib\site-packages\flask\app.py", line 1950, in full_dispatch_request
    rv = self.dispatch_request()
  File "C:\Users\aless\Anaconda3\envs\flask_env\lib\site-packages\flask\app.py", line 1936, in dispatch_request
    return self.view_functions[rule.endpoint](**req.view_args)
  File "C:\Users\aless\Desktop\AI\CORSI\web_flask\microblog\app\routes.py", line 199, in reset_password_request
    send_password_reset_email(user)
  File "C:\Users\aless\Desktop\AI\CORSI\web_flask\microblog\app\email.py", line 15, in send_password_reset_email
    send_email('[Microblog] Reset your password',
  File "C:\Users\aless\Desktop\AI\CORSI\web_flask\microblog\app\email.py", line 11, in send_email
    mail.send(msg)
  File "C:\Users\aless\Anaconda3\envs\flask_env\lib\site-packages\flask_mail.py", line 491, in send
    with self.connect() as connection:
  File "C:\Users\aless\Anaconda3\envs\flask_env\lib\site-packages\flask_mail.py", line 144, in __enter__
    self.host = self.configure_host()
  File "C:\Users\aless\Anaconda3\envs\flask_env\lib\site-packages\flask_mail.py", line 158, in configure_host
    host = smtplib.SMTP(self.mail.server, self.mail.port)
  File "C:\Users\aless\Anaconda3\envs\flask_env\lib\smtplib.py", line 253, in __init__
    (code, msg) = self.connect(host, port)
  File "C:\Users\aless\Anaconda3\envs\flask_env\lib\smtplib.py", line 339, in connect
    self.sock = self._get_socket(host, port, self.timeout)
  File "C:\Users\aless\Anaconda3\envs\flask_env\lib\smtplib.py", line 308, in _get_socket
    return socket.create_connection((host, port), timeout,
  File "C:\Users\aless\Anaconda3\envs\flask_env\lib\socket.py", line 808, in create_connection
    raise err
  File "C:\Users\aless\Anaconda3\envs\flask_env\lib\socket.py", line 796, in create_connection
    sock.connect(sa)
ConnectionRefusedError: [WinError 10061] No connection could be made because the target machine actively refused it
2020-07-27 16:14:42,257 INFO: Microblog startup [in C:\Users\aless\Desktop\AI\CORSI\web_flask\microblog\app\__init__.py:47]
2020-07-27 16:15:29,798 INFO: Microblog startup [in C:\Users\aless\Desktop\AI\CORSI\web_flask\microblog\app\__init__.py:47]
2020-07-27 16:17:34,803 ERROR: Exception on /reset_password_request [POST] [in C:\Users\aless\Anaconda3\envs\flask_env\lib\site-packages\flask\app.py:1891]
Traceback (most recent call last):
  File "C:\Users\aless\Anaconda3\envs\flask_env\lib\site-packages\flask\app.py", line 2447, in wsgi_app
    response = self.full_dispatch_request()
  File "C:\Users\aless\Anaconda3\envs\flask_env\lib\site-packages\flask\app.py", line 1952, in full_dispatch_request
    rv = self.handle_user_exception(e)
  File "C:\Users\aless\Anaconda3\envs\flask_env\lib\site-packages\flask\app.py", line 1821, in handle_user_exception
    reraise(exc_type, exc_value, tb)
  File "C:\Users\aless\Anaconda3\envs\flask_env\lib\site-packages\flask\_compat.py", line 39, in reraise
    raise value
  File "C:\Users\aless\Anaconda3\envs\flask_env\lib\site-packages\flask\app.py", line 1950, in full_dispatch_request
    rv = self.dispatch_request()
  File "C:\Users\aless\Anaconda3\envs\flask_env\lib\site-packages\flask\app.py", line 1936, in dispatch_request
    return self.view_functions[rule.endpoint](**req.view_args)
  File "C:\Users\aless\Desktop\AI\CORSI\web_flask\microblog\app\routes.py", line 199, in reset_password_request
    send_password_reset_email(user)
  File "C:\Users\aless\Desktop\AI\CORSI\web_flask\microblog\app\email.py", line 15, in send_password_reset_email
    send_email('[Microblog] Reset your password',
  File "C:\Users\aless\Desktop\AI\CORSI\web_flask\microblog\app\email.py", line 11, in send_email
    mail.send(msg)
  File "C:\Users\aless\Anaconda3\envs\flask_env\lib\site-packages\flask_mail.py", line 491, in send
    with self.connect() as connection:
  File "C:\Users\aless\Anaconda3\envs\flask_env\lib\site-packages\flask_mail.py", line 144, in __enter__
    self.host = self.configure_host()
  File "C:\Users\aless\Anaconda3\envs\flask_env\lib\site-packages\flask_mail.py", line 158, in configure_host
    host = smtplib.SMTP(self.mail.server, self.mail.port)
  File "C:\Users\aless\Anaconda3\envs\flask_env\lib\smtplib.py", line 253, in __init__
    (code, msg) = self.connect(host, port)
  File "C:\Users\aless\Anaconda3\envs\flask_env\lib\smtplib.py", line 339, in connect
    self.sock = self._get_socket(host, port, self.timeout)
  File "C:\Users\aless\Anaconda3\envs\flask_env\lib\smtplib.py", line 308, in _get_socket
    return socket.create_connection((host, port), timeout,
  File "C:\Users\aless\Anaconda3\envs\flask_env\lib\socket.py", line 808, in create_connection
    raise err
  File "C:\Users\aless\Anaconda3\envs\flask_env\lib\socket.py", line 796, in create_connection
    sock.connect(sa)
ConnectionRefusedError: [WinError 10061] No connection could be made because the target machine actively refused it
2020-07-27 16:38:40,827 INFO: Microblog startup [in C:\Users\aless\Desktop\AI\CORSI\web_flask\microblog\app\__init__.py:47]
2020-07-27 16:40:37,162 ERROR: Exception on /reset_password_request [POST] [in C:\Users\aless\Anaconda3\envs\flask_env\lib\site-packages\flask\app.py:1891]
Traceback (most recent call last):
  File "C:\Users\aless\Anaconda3\envs\flask_env\lib\site-packages\flask\app.py", line 2447, in wsgi_app
    response = self.full_dispatch_request()
  File "C:\Users\aless\Anaconda3\envs\flask_env\lib\site-packages\flask\app.py", line 1952, in full_dispatch_request
    rv = self.handle_user_exception(e)
  File "C:\Users\aless\Anaconda3\envs\flask_env\lib\site-packages\flask\app.py", line 1821, in handle_user_exception
    reraise(exc_type, exc_value, tb)
  File "C:\Users\aless\Anaconda3\envs\flask_env\lib\site-packages\flask\_compat.py", line 39, in reraise
    raise value
  File "C:\Users\aless\Anaconda3\envs\flask_env\lib\site-packages\flask\app.py", line 1950, in full_dispatch_request
    rv = self.dispatch_request()
  File "C:\Users\aless\Anaconda3\envs\flask_env\lib\site-packages\flask\app.py", line 1936, in dispatch_request
    return self.view_functions[rule.endpoint](**req.view_args)
  File "C:\Users\aless\Desktop\AI\CORSI\web_flask\microblog\app\routes.py", line 199, in reset_password_request
    send_password_reset_email(user)
  File "C:\Users\aless\Desktop\AI\CORSI\web_flask\microblog\app\email.py", line 15, in send_password_reset_email
    send_email('[Microblog] Reset your password',
  File "C:\Users\aless\Desktop\AI\CORSI\web_flask\microblog\app\email.py", line 11, in send_email
    mail.send(msg)
  File "C:\Users\aless\Anaconda3\envs\flask_env\lib\site-packages\flask_mail.py", line 491, in send
    with self.connect() as connection:
  File "C:\Users\aless\Anaconda3\envs\flask_env\lib\site-packages\flask_mail.py", line 144, in __enter__
    self.host = self.configure_host()
  File "C:\Users\aless\Anaconda3\envs\flask_env\lib\site-packages\flask_mail.py", line 158, in configure_host
    host = smtplib.SMTP(self.mail.server, self.mail.port)
  File "C:\Users\aless\Anaconda3\envs\flask_env\lib\smtplib.py", line 253, in __init__
    (code, msg) = self.connect(host, port)
  File "C:\Users\aless\Anaconda3\envs\flask_env\lib\smtplib.py", line 339, in connect
    self.sock = self._get_socket(host, port, self.timeout)
  File "C:\Users\aless\Anaconda3\envs\flask_env\lib\smtplib.py", line 308, in _get_socket
    return socket.create_connection((host, port), timeout,
  File "C:\Users\aless\Anaconda3\envs\flask_env\lib\socket.py", line 808, in create_connection
    raise err
  File "C:\Users\aless\Anaconda3\envs\flask_env\lib\socket.py", line 796, in create_connection
    sock.connect(sa)
ConnectionRefusedError: [WinError 10061] No connection could be made because the target machine actively refused it
2020-07-27 16:57:35,263 INFO: Microblog startup [in C:\Users\aless\Desktop\AI\CORSI\web_flask\microblog\app\__init__.py:47]
